Workbook
Name FintiOwnerList: OwnerLists!$A$2:$A$5
Name FintiOwnerCol: 'Dealer Master'!$BZ$5:$BZ$1021
Name ReadyForRateSheetsCol: 'Dealer Master'!$CA$5:$CA$1021
Name ShawHoldCol: 'Dealer Master'!$CB$5:$CB$1021

Sheet Onboarding Procedures
A1: HOME IMPROVEMENT DEALER ONBOARDING - THE PROCESS
A2: Built from Shawn's Sept 1, 2026 walkthroughs and organized around the Dealer Master tracker: every merchant sits in one Overall Status, and this page tells you what that status means, what you do, and what you type. Updated Sept 2, 2026.
A4: NEW ONBOARDING REP - GET SET UP (DAY 1)
A5: 1. Access | C5: Get your @getfinti.com mailbox, access to the shared merchantonboarding@getfinti.com inbox (all lender and dealer email lives there - always cc it), a login to the Finti portal (app.getfinti.com) with Merchants access, and edit rights to this workbook (Microsoft 365 > Excel > Home Improvement Boarding Tracker V2).
A6: 2. Read these tabs | C6: This tab top to bottom, then DEALER MASTER - HOW TO at the bottom (what the colors mean and what you type), then the SUNLIGHT / SERVICE / Foundation tabs (how to submit to each lender and who to contact). Add yourself to the rep list on the Add Merchant tab if you are missing.
A7: 3. Shadow one merchant | C7: Open a dealer that is already LIVE DLR on Dealer Master and walk it backwards: its row here, its record in the Finti portal (application pages 1-5, Store / Location, Provider credentials), and the email thread in merchantonboarding. That is the whole process end to end.
A8: 4. Know the people | C8: Shawn Hanks - onboarding lead, lender relationships, on the first training calls. Brittany (Brit) - onboarding ops, works from merchantonboarding. Brittany Coutu - Rate Sheet Manager. Jennifer - Service Finance. Jessica Gill / Kobe - Foundation. Alan - Finti portal / dev. Steve - sales leadership.
A9: 5. Email habits | C9: Send from your own @getfinti address, always cc merchantonboarding, cc the sales rep except on sensitive questions (revenue, socials). Draft with Copilot from previously sent emails. Never email a dealer from memory - open their row first, and log the date in Last Status Update Emailed after you send.
A10: 6. Your first week | C10: Day 1: setup + shadow. Day 2: run the EVERY DAY loop with Brit and work Waiting on Dealer rows. Day 3+: take new merchants in the Finti portal start to finish. Ask Shawn before your first lender submission and your first credential load.
A12: EVERY DAY - THREE CHECKS, IN THIS ORDER
A13: 1. Finti portal > Merchants | C13: New merchants are at the top. Anything you have not touched is job #1 - approve it, review it, and get it onto Dealer Master today. Nobody in the company should see a red stoplight.
A14: 2. Dealer Master | C14: Black (Priority 1) rows first, then orange cells (someone needs to move), then Days Since Update - anything 3+ days old gets a follow-up today.
A15: 3. merchantonboarding inbox | C15: Look for lender credentials / API keys, lender questions, or a dealer saying "done." Each one moves a merchant to its next status below.
A16: The one rule | C16: Whenever you do anything for a dealer, update its row right then: lender status, Merchant To-Do, date emailed. If it is not on the sheet, nobody knows.
A18: THE PROCESS - ONE ROW PER OVERALL STATUS ON DEALER MASTER
A19: Overall Status | B19: What it means | C19: What you do | D19: What you type on Dealer Master
A20: NEW (in Finti portal, not on the sheet yet) | B20: A merchant finished page 1 of the application and appeared at the top of the Finti portal. | C20: 1. Approve them as a dealer. Click Edit and walk pages 1-5. Note every missing item - each becomes a line in your email. 2. Check which lenders the rep selected and whether any were bypassed (dealer already has that lender - never resubmit those). 3. Pages 1-2: owner as primary contact, revenue and years in business make sense (odd numbers -> email Steve). Page 3: website + review link (Google them if blank). Page 4: two bank statements + voided check (voided check goes in the Articles of Incorporation slot). Page 5: boxes, signatures, Save and Continue, close -> three DocuSigns go out. 4. Set up the Store / Location if it is missing (Merchant > Store: same as corporate, business name in both name fields, owner contact, bank routing + account) - without it the dealer cannot log back in. 5. Add them on the Add Merchant tab. | D20: Add Merchant tab: name, contacts, vertical, rep, Priority 1-3, Application Date, Merchant To-Do = the list of what is missing. Each lender: Not Started, N/A (not applying / Chowder non-HVAC), or No Min RQ (does not meet that lender's minimums). The row now reads Waiting on Dealer (if a To-Do is open) or Application Submitted.
A21: WAITING ON DEALER | B21: The dealer owes us something (To-Do box unchecked). This is the status Shawn wants worked hardest - the ball is in the dealer's court and only we can push it. | C21: 1. Email the dealer the Action Required email (template 1): every missing item, which page it is on, use Forgot Password, Save and Continue on every page, sign the DocuSigns, reply when done. 2. In the Finti portal flip the stoplight red -> yellow and post "@rep@getfinti.com - application incomplete, emailed dealer [date]". 3. No reply in 3 days? Send the same email again. Repeat every 3 days until they respond (Shawn wants this automated). 4. When the dealer says done, re-check pages 1-5 and DocuSign. Still missing something? Repeat step 1. | D21: Merchant To-Do = what they still owe. Last Status Update Emailed = today, every time you email. Everything landed? Tick the To-Do Done box - the row stops being orange and moves to Application Submitted / Waiting on Lender.
A22: APPLICATION SUBMITTED / WAITING ON LENDER | B22: Application Submitted: complete, but at least one lender is still Not Started. Waiting on Lender: submitted, waiting on the lender's ~2-week due diligence. | C22: 1. Submit to each lender that is Not Started, using the instructions on the SUNLIGHT / SERVICE / Foundation tabs. Existing-lender dealers: bypass, and ask them for their dealer / merchant ID instead. 2. Email the dealer the Submitted email (template 2) and update the stoplight + @ the rep. 3. Service Finance only: email Jennifer the SAME DAY - "we submitted [dealer], is it in your system?" (submissions have gone missing before). 4. Watch merchantonboarding for lender questions; answer them or forward to the dealer the same day. 5. Credentials / API keys arrive -> record them on Dealer Details, then Finti > Merchants > dealer > Location > Provider > Add Provider (strip spaces from the key; Foundation username = dealer ID; leave Valid Till). Do NOT tell the dealer yet. | D22: Each lender: Submitted when you submit; Approved when the credentials are loaded; Declined if the lender says no. Last Status Update Emailed = date of the submitted email. All applied lenders Approved -> the row moves to Rate Sheet on its own.
A23: RATE SHEET | B23: Every applied lender is approved and loaded in Finti. Brittany Coutu's queue - the dealer needs to pick rates before anyone can be trained. | C23: 1. Email Brittany Coutu (template 4) with Shawn and the sales rep on the thread: credentials are in Finti, please send the rate sheets, and once the dealer responds set up the lender and get them training-ready. 2. Optional: tell the dealer "Congratulations - next step is Brittany sending you the [lender] rate sheet to select your rates." 3. Order matters: Brittany sends rates -> dealer selects -> Brittany builds the rate sheet and loads the programs. Never ask her to "set them up" first. A dealer with a better rate sheet of their own keeps it. | D23: Rate Sheet = Yes for each lender once Brittany has built it. Programs Loaded = Yes when the programs are in Finti. The row moves to Training on its own.
A24: TRAINING | B24: Rate sheets are built; the dealer has not been trained. Nothing can go live before training. | C24: 1. Rate sheet meeting (Brittany Coutu + you + the sales rep) with the dealer's top person: connect the rate sheets and show them how to add users. 2. Dealer adds their users and sends their reps logins. 3. Training meeting with the dealer's reps - the sales rep attends, Shawn on the first few. | D24: Training = Yes for each lender once its training is done. Every applied lender Active + Rate Sheet Yes + Training Yes -> the row reads LIVE DLR.
A25: ACTIVE / LIVE DLR | B25: Active: at least one lender is live. LIVE DLR: every applied lender is live, rate-sheeted and trained - onboarding is finished. | C25: 1. Tell the dealer they are live and can run applications. Set the stoplight to green and @ the rep. 2. Tick the To-Do box and log the date. 3. Anything still Approved-but-not-Active means one lender is behind - chase that lender's rate sheet or training, not the dealer. | D25: Lender = Active once it is turned on. Live flags are automatic. Nothing else to type - the row is done.
A26: DEAD | B26: Every real lender declined (N/A and No Min RQ do not count). One approval anywhere means a dealer is never Dead. | C26: Stop working it. Tell the rep. Do not re-excite the dealer until a new lender joins or their numbers change - then set the lender back to Not Started (or No Min RQ -> Not Started) and it re-enters the process. | D26: Lender = Declined for each lender that said no. The row turns red on its own.
A28: PRIORITY - SET IT ON EVERY MERCHANT
A29: 1 - Top (black row) | C29: Connected to RoofLink, SalesRabbit or another channel partner sending a lot of business; OR a big account (about $1M a month in financing already); OR Steve / leadership asks. Work these first, every day.
A30: 2 - Middle | C30: North of $1M a year in revenue and at least a year in business (ideally two or more).
A31: 3 - Small | C31: Mom-and-pop: about $1M a year or less, maybe under a year old. Will not meet most lender minimums - submit to Foundation only.
A33: STOPLIGHT IN THE FINTI PORTAL - WHAT THE SALES REP SEES
A34: Red / Yellow / Green | C34: Red = untouched (nobody should ever see it). Yellow = in process - set it the moment you start, and update the message at each status change. Green = live.
A35: Tagging the rep | C35: Tagging @rep@getfinti.com texts and emails them - do it at every status change. Reps cannot see this sheet; the stoplight is how they find out. Most problems sit with the merchant, not the rep - email the merchant directly and use the stoplight to keep the rep informed.
A37: LENDER CHEAT SHEET
A38: The stack | C38: One prime, one near-prime, one sub-prime per dealer where applicable - not every lender. Never submit a new application to a lender the dealer already has; bypass it and use their existing dealer ID.
A39: Service Finance (prime) | C39: Needs a web presence, ~1 year in business, ~$1M revenue; asks for a license number. Email Jennifer the same day you submit. After approval, get the Service Finance Merchant ID - that is all Finti needs to add the provider.
A40: Sunlight (prime / near-prime) | C40: ~2 years in business plus revenue minimums; needs two bank statements and a voided check. No submission issues so far.
A41: Foundation (sub-prime) | C41: No minimums - every dealer can go here; Priority 3 goes ONLY here. Needs a dealer email. Foundation emails the dealer directly for anything missing. Credentials come from Jessica Gill; username = dealer ID.
A42: Chowder / US Bank | C42: Chowder: HVAC only, always last in the stack, N/A for everyone else (the sheet does this). US Bank: newest lender, same flow as the others.
A43: Does not qualify | C43: Mark that lender No Min RQ, not Declined - it can be applied later when the dealer grows.
A45: EMAIL TEMPLATES (adjust the list for each dealer)
A46: 1. Action required (Waiting on Dealer) | C46: Subject: Action required: complete your Finti application Thank you for applying with Finti. We have reviewed your application and just need a few final items before we can continue. Please log into app.getfinti.com (use Forgot Password if needed) and complete the following: - Page 3 (Insights): [fields], plus your current website and your review / reputation link. - Page 4 (Documents): your two most recent bank statements and a voided check (upload the voided check in the Articles of Incorporation section). - Page 5 (Agreements): all signature fields and certification boxes, then Save and Continue and close the page. - Sign the three DocuSign agreements you will receive after page 5. Once everything is complete, please reply to this email and we will submit you to the lenders right away.
A47: 2. Submitted (Waiting on Lender) | C47: We have submitted you to [lenders]. Please be on the lookout for emails and phone calls from the lenders as they complete their due diligence - on average about two weeks. Please be responsive and quick with anything they ask for so we can expedite the process, and let us know as soon as you hear of your approval.
...

Sheet README - Start Here
B1: Dealer Boarding Tracker — Evan's Draft
B2: Built from scratch in a blank workbook, for team review.
B4: DRAFT. Separate file. The shared tracker in Shawn's OneDrive has not been touched.
B6: Nothing was lost
B7: All 2616 non-empty cells from all 11 tabs of the original workbook are accounted for in this file. The 'Data Check' tab is the receipt. Merchant data is split between the new Dealer Master (short, color-coded status) and Dealer Details (the original wording, verbatim, with the original row number beside it). The reference tabs are flattened onto 'Lender Reference', and the 32 screenshots are transcribed on 'Screenshot Text'. The original workbook, images and all, is untouched and remains the archive.
B9: What's new on Dealer Master
B10: • Merchant To-Do — the single 'what happens next' column, seeded with the original notes.
B11: • Last Status Update Emailed — when you last emailed the merchant an update.
B12: • Days Since Update — fills in on its own; amber past 14 days, red past 30, counted at the top.
B13: • A Live toggle per lender (SF / SL / FF / CW / USB), separate from application status, so 'approved' and 'actually switched on' stop sharing a cell.
B14: • Lenders Live — how many of the five are live for that merchant.
B15: • POP Sent is a Yes/No toggle.
... B51: 3. On approval I can make this the shared file, or apply the structure to the existing one.

Sheet Add Merchant
A1: ADD A NEW MERCHANT
A2: Fill in the yellow cells, then click the Add Merchant button. Required: Legal Business Name, Email, and at least one lender set to Yes. The row is added to Dealer Master with every column defaulted, then this form clears. | D2: Added JAAR BUILDERS to Dealer Master row 52 (lenders: SF, FF). Overall Status: Application Submitted | I2: STATE PICKER - tick every state this dealer is active in
I3: FALSE | J3: Nationwide (all 50) - overrides the ticks below | S3: MANUAL REP LIST - add reps here who are not on a merchant yet
A4: Legal Business Name * | D4: Existing reps (auto - add new reps in the MANUAL REP LIST, column S) | E4: Rep email | G4: Channel partners (dropdown source) | S4: Rep | T4: Rep email
A5: DBA | D5: {=IFERROR(_xlfn._xlws.SORT(_xlfn.UNIQUE(_xlfn._xlws.FILTER(_xlfn.VSTACK('Dealer Master'!G5:G1028,S5:S104),_xlfn.VSTACK('Dealer Master'!G5:G1028,S5:S104)<>""))),"")} -> Brayden Page | E5: {=IFERROR(_xlfn.XLOOKUP(_xlfn.ANCHORARRAY(D5),_xlfn.VSTACK('Dealer Master'!G5:G1028,S5:S104),_xlfn.VSTACK('Dealer Master'!H5:H1028,T5:T104),""),"")} -> Brayden.page@getfinti.com | G5: {=IFERROR(_xlfn._xlws.SORT(_xlfn.UNIQUE(_xlfn._xlws.FILTER('Dealer Master'!C5:C1028,'Dealer Master'!C5:C1028<>""))),"")} -> Sales Rabbit | I5: FALSE | J5: AL | K5: Alabama | L5: FALSE | M5: LA | N5: Louisiana | O5: FALSE | P5: OH | Q5: Ohio | S5: Mark Robichaud | T5: markchmand@gmail.com
A6: Merchant Name (contact) | D6: chris Shipley | E6: chris@getfinti.com | I6: FALSE | J6: AK | K6: Alaska | L6: FALSE | M6: ME | N6: Maine | O6: FALSE | P6: OK | Q6: Oklahoma | S6: Ethan Meturi | T6: Ethan.meturi@getfinti.com
A7: Phone # | D7: Clint Cowley | E7: sales@gowefund.com, clint@gowefund.com | I7: FALSE | J7: AZ | K7: Arizona | L7: FALSE | M7: MD | N7: Maryland | O7: FALSE | P7: OR | Q7: Oregon | S7: chris Shipley | T7: chris@getfinti.com
A8: Email * | D8: David Yates | E8: David.yates@getfinti.com | I8: FALSE | J8: AR | K8: Arkansas | L8: FALSE | M8: MA | N8: Massachusetts | O8: FALSE | P8: PA | Q8: Pennsylvania | S8: Brayden Page | T8: Brayden.page@getfinti.com
A9: Rep | D9: Doug Yates | E9: doug.yates@getfinti.com | I9: FALSE | J9: CA | K9: California | L9: FALSE | M9: MI | N9: Michigan | O9: FALSE | P9: RI | Q9: Rhode Island | S9: Payden Yates | T9: Payden.yates@getfinti.com
A10: Rep Email | B10: =IFERROR(VLOOKUP($B$9,$D$5:$E$500,2,FALSE),"") | D10: Ethan Meturi | E10: Ethan.meturi@getfinti.com | I10: FALSE | J10: CO | K10: Colorado | L10: FALSE | M10: MN | N10: Minnesota | O10: FALSE | P10: SC | Q10: South Carolina | S10: Doug Yates | T10: Doug.Yates@getfinti.com
A11: Vertical | D11: Evan Young | E11: evanyoung@getfinti.com | I11: FALSE | J11: CT | K11: Connecticut | L11: FALSE | M11: MS | N11: Mississippi | O11: FALSE | P11: SD | Q11: South Dakota | S11: sales Rabbit | T11: sales rabbit
A12: Priority (1-3) | D12: Gentry Knight | E12: gentryknight2010@icloud.com | I12: FALSE | J12: DE | K12: Delaware | L12: FALSE | M12: MO | N12: Missouri | O12: FALSE | P12: TN | Q12: Tennessee
A13: Application Date | B13: =TODAY() -> 46288 | D13: Heriberto Rivera | E13: yennikayadiel@gmail.com | I13: FALSE | J13: FL | K13: Florida | L13: FALSE | M13: MT | N13: Montana | O13: FALSE | P13: TX | Q13: Texas
A14: LENDERS TO SUBMIT (Yes/No) | D14: Kyle Fransen | E14: kyle@getfinti.com | I14: FALSE | J14: GA | K14: Georgia | L14: FALSE | M14: NE | N14: Nebraska | O14: FALSE | P14: UT | Q14: Utah
A15: Service Finance | B15: No | D15: Mark Robichaud | E15: markchmand@gmail.com | I15: FALSE | J15: HI | K15: Hawaii | L15: FALSE | M15: NV | N15: Nevada | O15: FALSE | P15: VT | Q15: Vermont
A16: Sunlight | B16: No | D16: Payden Yates | E16: payden.yates@getfinti.com | I16: FALSE | J16: ID | K16: Idaho | L16: FALSE | M16: NH | N16: New Hampshire | O16: FALSE | P16: VA | Q16: Virginia
A17: Foundation | B17: No | D17: Rob Garcia | E17: robsudden24@icloud.com | I17: FALSE | J17: IL | K17: Illinois | L17: FALSE | M17: NJ | N17: New Jersey | O17: FALSE | P17: WA | Q17: Washington
A18: Chowder (auto: HVAC only) | B18: =IF(ISNUMBER(SEARCH("HVAC",B11)),"Yes","No") -> No | D18: Ryan Tall | E18: ryantall11@gmail.com | I18: FALSE | J18: IN | K18: Indiana | L18: FALSE | M18: NM | N18: New Mexico | O18: FALSE | P18: WV | Q18: West Virginia
A19: US Bank | B19: No | D19: sales Rabbit | E19: sales rabbit | I19: FALSE | J19: IA | K19: Iowa | L19: FALSE | M19: NY | N19: New York | O19: FALSE | P19: WI | Q19: Wisconsin
A20: Merchant To-Do | D20: Scott Coombs | E20: scottbcoombs@gmail.com | I20: FALSE | J20: KS | K20: Kansas | L20: FALSE | M20: NC | N20: North Carolina | O20: FALSE | P20: WY | Q20: Wyoming
A21: Channel Partner | D21: Scott Williams | E21: scott.williams.aftr@gmail.com | I21: FALSE | J21: KY | K21: Kentucky | L21: FALSE | M21: ND | N21: North Dakota | O21: FALSE | P21: DC | Q21: Washington DC
A22: States Active | B22: {=IF((I3<>"")*(UPPER(I3&"")<>"FALSE"),"Nationwide",_xlfn.TEXTJOIN(", ",TRUE,_xlfn.TEXTJOIN(", ",TRUE,IF((I5:I21<>"")*(UPPER(I5:I21&"")<>"FALSE"),J5:J21,"")),_xlfn.TEXTJOIN(", ",TRUE,IF((L5:L21<>"")*(UPPER(L5:L21&"")<>"FALSE"),M5:M21,"")),_xlfn.TEXTJOIN(", ",TRUE,IF((O5:O21<>"")*(UPPER(O5:O21&"")<>"FALSE"),P5:P21,""))))} | D22: Shawn Hanks | E22: Shawn@getfinti.com
A23: Tick the boxes in the STATE PICKER to the right (columns I-Q). | D23: Spencer Gradley | E23: spencer.gradley@getfinti.com
D24: Spencer Jackson | E24: app.sj@icloud.com
D25: Steve Stonebraker | E25: stonebraker@getfinti.com
D26: Trevor Young | E26: Trevor.young@getfinti.com
D27: Tyler Mickelsen | E27: tyler@getfinti.com
D28: Tyler Story | E28: tylerstory32@gmail.com
A29: Finti Owner | B29: Unassigned
A31: Same dropdown as Dealer Master. Run Add Merchant is an existing Office Script button, not VBA, and it does not copy this cell. Set Finti Owner on the new Dealer Master row. Blank counts as Unassigned.
A32: =IF($B$18="Yes","CHOWDER APPLICATION INFORMATION","Chowder section appears when Vertical includes HVAC") -> Chowder section appears when Vertical includes HVAC
A33: Chowder Status | B33: =IF($B$18<>"Yes","",_xlfn.LET(_xlpm.m,_xlfn.TEXTJOIN(", ",TRUE,IF(TRIM(B36&"")="","License Holder",""),IF(TRIM(B37&"")="","License #",""),IF(TRIM(B38&"")="","EIN",""),IF(TRIM(B40&"")="","Website",""),IF(TRIM(B41&"")="","Address",""),IF(TRIM(B43&"")="","Contact First Name",""),IF(TRIM(B44&"")="","Contact Last Name",""),IF(TRIM(B46&"")="","Contact Email",""),IF(TRIM(B48&"")="","Owner First Name",""),IF(TRIM(B49&"")="","Owner Last Name",""),IF(TRIM(B51&"")="","Owner Email",""),IF(TRIM(B53&"")="","Bank Name",""),IF(TRIM(B54&"")="","Routing #",""),IF(TRIM(B55&"")="","Account #",""),IF(B57<>TRUE,"Business Registration doc",""),IF(B58<>TRUE,"HVAC License doc",""),IF(B59<>TRUE,"Voided Check doc",""),IF(AND(TRIM(B38&"")<>"",LEN(SUBSTITUTE(SUBSTITUTE(B38&"","-","")," ",""))<>9),"EIN must be 9 digits",""),IF(AND(TRIM(B54&"")<>"",NOT(AND(LEN(TRIM(B54&""))=9,ISNUMBER(--TRIM(B54&""))))),"Routing # must be 9 digits",""),IF(AND(TRIM(B46&"")<>"",ISERROR(SEARCH("@",B46))),"Contact Email invalid",""),IF(AND(TRIM(B51&"")<>"",ISERROR(SEARCH("@",B51))),"Owner Email invalid","")),IF(_xlpm.m="","READY FOR CHOWDER SUBMISSION","MISSING REQUIRED INFORMATION: "&_xlpm.m)))
A34: BUSINESS INFORMATION
A35: Legal Entity Type
A36: HVAC License Holder Name *
A37: HVAC License Number *
A38: Tax ID / EIN *
A39: Business Start Year
A40: Website *
A41: Business Address *
...

Sheet Dealer Master
A1: At a glance: | BA1: DEFAULT
A2: SORT: DEFAULT ORDER | I2: ="Waiting on Dealer: "&COUNTIF(DealerMaster[Overall Status],"Waiting on Dealer") -> Waiting on Dealer: 16 | K2: ="Waiting on Lender: "&COUNTIF(DealerMaster[Overall Status],"Waiting on Lender") -> Waiting on Lender: 13 | L2: ="App Submitted: "&COUNTIF(DealerMaster[Overall Status],"Application Submitted") -> App Submitted: 2 | M2: ="Rate Sheet: "&COUNTIF(DealerMaster[Overall Status],"Rate Sheet") -> Rate Sheet: 3 | O2: ="LIVE DLR: "&COUNTIF(DealerMaster[Overall Status],"LIVE DLR") -> LIVE DLR: 4 | P2: Min Rq | T2: Min Rq | X2: Min Rq | AB2: Min Rq | AF2: Min Rq | BZ2: Existing dealers are Unassigned. Do not guess an owner. Rep is not Finti Owner.
I3: ="Active: "&COUNTIF(DealerMaster[Overall Status],"Active") -> Active: 3 | K3: ="Dead: "&COUNTIF(DealerMaster[Overall Status],"Dead") -> Dead: 4 | L3: ="P1 open To-Do: "&COUNTIFS(DealerMaster[Priority],1,DealerMaster[Merchant To-Do],"<>",DealerMaster[To-Do Done],FALSE) -> P1 open To-Do: 5 | M3: ="No update >3d: "&COUNTIFS(DealerMaster[Days Since Update],">3",DealerMaster[Overall Status],"<>Active",DealerMaster[Overall Status],"<>Dead",DealerMaster[Overall Status],"<>LIVE DLR") -> No update >3d: 11 | O3: ="Training: "&COUNTIF(DealerMaster[Overall Status],"Training") -> Training: 1 | P3: 1 Yr | R3: Rate Sheet | S3: Training | T3: 2 Yr $1M | V3: Rate sheet | W3: Training | X3: No Min Rq | Z3: Rate Sheet | AA3: Training | AB3: No Min Rq | AD3: Rate sheet | AE3: Training | AF3: 1 Yr | AI3: Training
A4: Legal Business Name | B4: DBA | C4: Channel Partner | D4: Merchant Name | E4: Phone # | F4: Email | G4: Rep | H4: Rep Email | I4: Vertical | J4: States Active | K4: Priority | L4: Overall Status | M4: Application Date | N4: Welcome Email Sent | O4: Lender Order | P4: Service Finance | Q4: SF Submitted | R4: SF Rate Sheet | S4: SF Training | T4: Sunlight | U4: SL Submitted | V4: SL Rate Sheet | W4: SL Training | X4: Foundation | Y4: FF Submitted | Z4: FF Rate Sheet | AA4: FF Training | AB4: Chowder | AC4: CH Submitted | AD4: CH Rate Sheet | AE4: CH Training | AF4: US Bank | AG4: USB Submitted | AH4: USB Rate Sheet | AI4: USB Training | AJ4: Merchant To-Do | AK4: To-Do Done | AL4: Lenders Live | AM4: Last Status Update Emailed | AN4: Days Since Update | AO4: Divider | AP4: Service Finance API Code | AQ4: Service Finance States Active | AR4: Sunlight API Code | AS4: Sunlight States Active | AT4: Foundation API Code | AU4: Foundation States Active | AV4: Chowder API Code | AW4: Chowder States Active | AX4: US Bank API Code | AY4: US Bank States Active | AZ4: Divider 2 | BA4: Sort Key | BB4: Sort Temp | BC4: Divider 3 | BD4: CH Legal Entity Type | BE4: CH License Holder | BF4: CH License Number | BG4: CH EIN | BH4: CH Business Start Year | BI4: CH Website | BJ4: CH Business Address | BK4: CH Contact First Name | BL4: CH Contact Last Name | BM4: CH Contact Phone | BN4: CH Contact Email | BO4: CH Owner First Name | BP4: CH Owner Last Name | BQ4: CH Owner Phone | BR4: CH Owner Email | BS4: CH Bank Name | BT4: CH Routing Number | BU4: CH Account Number | BV4: CH Doc Business Registration | BW4: CH Doc HVAC License | BX4: CH Doc Voided Check | BY4: CH Info Saved | BZ4: Finti Owner | CA4: Ready for rate sheets | CB4: Shaw Hold | CC4: Handoff note
A5: Vivid Windows LLC | B5: Vivid Windows | D5: Biss Larsen | E5: 801-557-9860 | F5: biss.larsen@vividwindows.com | G5: Kyle Fransen | H5: kyle@getfinti.com | I5: windows | L5: =IF($A5="","",_xlfn.LET(_xlpm.ns,(--($P5="Ready 2 Submit"))+(--($T5="Ready 2 Submit"))+(--($X5="Ready 2 Submit"))+(--($AB5="Ready 2 Submit"))+(--($AF5="Ready 2 Submit")),_xlpm.wd,(--($P5="Waiting on Dealer"))+(--($T5="Waiting on Dealer"))+(--($X5="Waiting on Dealer"))+(--($AB5="Waiting on Dealer"))+(--($AF5="Waiting on Dealer")),_xlpm.sb,(--($P5="Submitted"))+(--($T5="Submitted"))+(--($X5="Submitted"))+(--($AB5="Submitted"))+(--($AF5="Submitted")),_xlpm.ap,(--($P5="Approved"))+(--($T5="Approved"))+(--($X5="Approved"))+(--($AB5="Approved"))+(--($AF5="Approved")),_xlpm.ac,(--($P5="Active"))+(--($T5="Active"))+(--($X5="Active"))+(--($AB5="Active"))+(--($AF5="Active")),_xlpm.dc,(--($P5="Declined"))+(--($T5="Declined"))+(--($X5="Declined"))+(--($AB5="Declined"))+(--($AF5="Declined")),_xlpm.aRS,(--($P5="Active"))*(--($R5="Yes"))+(--($T5="Active"))*(--($V5="Yes"))+(--($X5="Active"))*(--($Z5="Yes"))+(--($AB5="Active"))*(--($AD5="Yes"))+(--($AF5="Active"))*(--($AH5="Yes")),_xlpm.aDn,(--($P5="Active"))*(--($R5="Yes"))*(--((($S5="Yes")+($S5=TRUE))>0))+(--($T5="Active"))*(--($V5="Yes"))*(--((($W5="Yes")+($W5=TRUE))>0))+(--($X5="Active"))*(--($Z5="Yes"))*(--((($AA5="Yes")+($AA5=TRUE))>0))+(--($AB5="Active"))*(--($AD5="Yes"))*(--((($AE5="Yes")+($AE5=TRUE))>0))+(--($AF5="Active"))*(--($AH5="Yes"))*(--((($AI5="Yes")+($AI5=TRUE))>0)),_xlpm.inPlay,_xlpm.ns+_xlpm.wd+_xlpm.sb+_xlpm.ap,IF(AND(_xlpm.ac>0,_xlpm.inPlay=0,_xlpm.aDn=_xlpm.ac),"LIVE DLR",IF(AND(_xlpm.aRS>0,_xlpm.aDn<_xlpm.aRS),"Training",IF(_xlpm.aRS>0,"Active",IF(AND(_xlpm.dc>0,_xlpm.inPlay+_xlpm.ac=0),"Dead",IF(OR($CA5="Yes",$CA5=TRUE),"Rate Sheet",IF(AND($AJ5<>"",$AK5=FALSE),"Waiting on Dealer",IF(_xlpm.sb>0,"Waiting on Lender",IF(AND(_xlpm.ap+_xlpm.ac>0,_xlpm.ns+_xlpm.wd=0),"Rate Sheet","Application Submitted")))))))))) -> LIVE DLR | M5: 46107 | N5: 46280 | O5: 1. Sunlight, 2. Service Finance, 3. Foundation Finance | P5: Active | Q5: 46274 | R5: Yes | S5: Yes | T5: Active | U5: 46274 | V5: Yes | W5: Yes | X5: Active | Y5: 46108 | Z5: Yes | AA5: Yes | AB5: N/A | AC5: =IF(OR(AC5="",AC5=0),IF($AB5="Submitted",TODAY(),""),AC5) | AD5: No | AE5: No | AF5: N/A | AG5: =IF(OR(AG5="",AG5=0),IF($AF5="Submitted",TODAY(),""),AG5) | AH5: No | AI5: No | AJ5: Active | AK5: TRUE | AL5: {=IF($A5="","",SUMPRODUCT((CHOOSE({1,2,3,4,5},$R5,$V5,$Z5,$AD5,$AH5)="Yes")*(((CHOOSE({1,2,3,4,5},$S5,$W5,$AA5,$AE5,$AI5)="Yes")+(CHOOSE({1,2,3,4,5},$S5,$W5,$AA5,$AE5,$AI5)=TRUE))>0)))} -> 3 | AN5: =IF(OR($A5="",$AM5=""),"",TODAY()-$AM5) | AP5: 227125330 | AR5: vividwindows-finti@sunlightfinancial.com; 800339 | AS5: ID, MT, WY, UT | pending: NV, CA | AT5: 35206000 | BA5: 1 | BZ5: Unassigned | CA5: No | CB5: =IF($A5="","",_xlfn.LET(_xlpm.sfp,AND($P5<>"",$P5<>"N/A",$P5<>"No Min RQ"),_xlpm.slp,AND($T5<>"",$T5<>"N/A",$T5<>"No Min RQ"),_xlpm.ffp,AND($X5<>"",$X5<>"N/A",$X5<>"No Min RQ"),_xlpm.chp,AND($AB5<>"",$AB5<>"N/A",$AB5<>"No Min RQ"),_xlpm.usp,AND($AF5<>"",$AF5<>"N/A",$AF5<>"No Min RQ"),_xlpm.n,_xlpm.sfp+_xlpm.slp+_xlpm.ffp+_xlpm.chp+_xlpm.usp,_xlpm.sub,(_xlpm.sfp*($P5="Submitted"))+(_xlpm.slp*($T5="Submitted"))+(_xlpm.ffp*($X5="Submitted"))+(_xlpm.chp*($AB5="Submitted"))+(_xlpm.usp*($AF5="Submitted")),_xlpm.term,(_xlpm.sfp*OR($P5="Approved",$P5="Declined"))+(_xlpm.slp*OR($T5="Approved",$T5="Declined"))+(_xlpm.ffp*OR($X5="Approved",$X5="Declined"))+(_xlpm.chp*OR($AB5="Approved",$AB5="Declined"))+(_xlpm.usp*OR($AF5="Approved",$AF5="Declined")),IF(_xlpm.n=0,"No applicable lenders",IF(_xlpm.sub>0,"Stays with Shaw - lender still Submitted",IF(_xlpm.term=_xlpm.n,"Clear - all applicable lenders Approved or Declined","Stays with Shaw - not all lenders Approved or Declined")))))
A6: Alta Water Bountiful LLC | B6: Water Protection 0ne | D6: Jonathan Ebert | E6: 801-450-5618 | F6: jono@drinkaltawater.com | G6: Kyle Fransen | H6: kyle@getfinti.com | I6: Water Treatment | L6: =IF($A6="","",_xlfn.LET(_xlpm.ns,(--($P6="Ready 2 Submit"))+(--($T6="Ready 2 Submit"))+(--($X6="Ready 2 Submit"))+(--($AB6="Ready 2 Submit"))+(--($AF6="Ready 2 Submit")),_xlpm.wd,(--($P6="Waiting on Dealer"))+(--($T6="Waiting on Dealer"))+(--($X6="Waiting on Dealer"))+(--($AB6="Waiting on Dealer"))+(--($AF6="Waiting on Dealer")),_xlpm.sb,(--($P6="Submitted"))+(--($T6="Submitted"))+(--($X6="Submitted"))+(--($AB6="Submitted"))+(--($AF6="Submitted")),_xlpm.ap,(--($P6="Approved"))+(--($T6="Approved"))+(--($X6="Approved"))+(--($AB6="Approved"))+(--($AF6="Approved")),_xlpm.ac,(--($P6="Active"))+(--($T6="Active"))+(--($X6="Active"))+(--($AB6="Active"))+(--($AF6="Active")),_xlpm.dc,(--($P6="Declined"))+(--($T6="Declined"))+(--($X6="Declined"))+(--($AB6="Declined"))+(--($AF6="Declined")),_xlpm.aRS,(--($P6="Active"))*(--($R6="Yes"))+(--($T6="Active"))*(--($V6="Yes"))+(--($X6="Active"))*(--($Z6="Yes"))+(--($AB6="Active"))*(--($AD6="Yes"))+(--($AF6="Active"))*(--($AH6="Yes")),_xlpm.aDn,(--($P6="Active"))*(--($R6="Yes"))*(--((($S6="Yes")+($S6=TRUE))>0))+(--($T6="Active"))*(--($V6="Yes"))*(--((($W6="Yes")+($W6=TRUE))>0))+(--($X6="Active"))*(--($Z6="Yes"))*(--((($AA6="Yes")+($AA6=TRUE))>0))+(--($AB6="Active"))*(--($AD6="Yes"))*(--((($AE6="Yes")+($AE6=TRUE))>0))+(--($AF6="Active"))*(--($AH6="Yes"))*(--((($AI6="Yes")+($AI6=TRUE))>0)),_xlpm.inPlay,_xlpm.ns+_xlpm.wd+_xlpm.sb+_xlpm.ap,IF(AND(_xlpm.ac>0,_xlpm.inPlay=0,_xlpm.aDn=_xlpm.ac),"LIVE DLR",IF(AND(_xlpm.aRS>0,_xlpm.aDn<_xlpm.aRS),"Training",IF(_xlpm.aRS>0,"Active",IF(AND(_xlpm.dc>0,_xlpm.inPlay+_xlpm.ac=0),"Dead",IF(OR($CA6="Yes",$CA6=TRUE),"Rate Sheet",IF(AND($AJ6<>"",$AK6=FALSE),"Waiting on Dealer",IF(_xlpm.sb>0,"Waiting on Lender",IF(AND(_xlpm.ap+_xlpm.ac>0,_xlpm.ns+_xlpm.wd=0),"Rate Sheet","Application Submitted")))))))))) -> LIVE DLR | M6: 46195 | N6: 46280 | P6: Declined | Q6: =IF(OR(Q6="",Q6=0),IF($P6="Submitted",TODAY(),""),Q6) | S6: No | T6: Declined | U6: =IF(OR(U6="",U6=0),IF($T6="Submitted",TODAY(),""),U6) | V6: No | W6: No | X6: Active | Y6: 46219 | Z6: Yes | AA6: Yes | AB6: N/A | AC6: =IF(OR(AC6="",AC6=0),IF($AB6="Submitted",TODAY(),""),AC6) | AD6: No | AE6: No | AF6: Active | AG6: 46274 | AH6: Yes | AI6: Yes | AJ6: 7/28 sent jono an email with Foundations rate sheet letting him know we can get started with them and asking him to pick the programs he wants to offer. | AK6: TRUE | AL6: {=IF($A6="","",SUMPRODUCT((CHOOSE({1,2,3,4,5},$R6,$V6,$Z6,$AD6,$AH6)="Yes")*(((CHOOSE({1,2,3,4,5},$S6,$W6,$AA6,$AE6,$AI6)="Yes")+(CHOOSE({1,2,3,4,5},$S6,$W6,$AA6,$AE6,$AI6)=TRUE))>0)))} -> 2 | AN6: =IF(OR($A6="",$AM6=""),"",TODAY()-$AM6) | AT6: 21174000 | AX6: 8047342103 | BA6: 2 | BZ6: Unassigned | CA6: No | CB6: =IF($A6="","",_xlfn.LET(_xlpm.sfp,AND($P6<>"",$P6<>"N/A",$P6<>"No Min RQ"),_xlpm.slp,AND($T6<>"",$T6<>"N/A",$T6<>"No Min RQ"),_xlpm.ffp,AND($X6<>"",$X6<>"N/A",$X6<>"No Min RQ"),_xlpm.chp,AND($AB6<>"",$AB6<>"N/A",$AB6<>"No Min RQ"),_xlpm.usp,AND($AF6<>"",$AF6<>"N/A",$AF6<>"No Min RQ"),_xlpm.n,_xlpm.sfp+_xlpm.slp+_xlpm.ffp+_xlpm.chp+_xlpm.usp,_xlpm.sub,(_xlpm.sfp*($P6="Submitted"))+(_xlpm.slp*($T6="Submitted"))+(_xlpm.ffp*($X6="Submitted"))+(_xlpm.chp*($AB6="Submitted"))+(_xlpm.usp*($AF6="Submitted")),_xlpm.term,(_xlpm.sfp*OR($P6="Approved",$P6="Declined"))+(_xlpm.slp*OR($T6="Approved",$T6="Declined"))+(_xlpm.ffp*OR($X6="Approved",$X6="Declined"))+(_xlpm.chp*OR($AB6="Approved",$AB6="Declined"))+(_xlpm.usp*OR($AF6="Approved",$AF6="Declined")),IF(_xlpm.n=0,"No applicable lenders",IF(_xlpm.sub>0,"Stays with Shaw - lender still Submitted",IF(_xlpm.term=_xlpm.n,"Clear - all applicable lenders Approved or Declined","Stays with Shaw - not all lenders Approved or Declined")))))
A7: Dirty Fence and Concrete | B7: Dirty Fence and Concrete | D7: Gentry Knight | E7: 801-389-4788 | F7: gentryknight2010@icloud.com | G7: Gentry Knight | H7: gentryknight2010@icloud.com | I7: Fencing | K7: 3 | L7: =IF($A7="","",_xlfn.LET(_xlpm.ns,(--($P7="Ready 2 Submit"))+(--($T7="Ready 2 Submit"))+(--($X7="Ready 2 Submit"))+(--($AB7="Ready 2 Submit"))+(--($AF7="Ready 2 Submit")),_xlpm.wd,(--($P7="Waiting on Dealer"))+(--($T7="Waiting on Dealer"))+(--($X7="Waiting on Dealer"))+(--($AB7="Waiting on Dealer"))+(--($AF7="Waiting on Dealer")),_xlpm.sb,(--($P7="Submitted"))+(--($T7="Submitted"))+(--($X7="Submitted"))+(--($AB7="Submitted"))+(--($AF7="Submitted")),_xlpm.ap,(--($P7="Approved"))+(--($T7="Approved"))+(--($X7="Approved"))+(--($AB7="Approved"))+(--($AF7="Approved")),_xlpm.ac,(--($P7="Active"))+(--($T7="Active"))+(--($X7="Active"))+(--($AB7="Active"))+(--($AF7="Active")),_xlpm.dc,(--($P7="Declined"))+(--($T7="Declined"))+(--($X7="Declined"))+(--($AB7="Declined"))+(--($AF7="Declined")),_xlpm.aRS,(--($P7="Active"))*(--($R7="Yes"))+(--($T7="Active"))*(--($V7="Yes"))+(--($X7="Active"))*(--($Z7="Yes"))+(--($AB7="Active"))*(--($AD7="Yes"))+(--($AF7="Active"))*(--($AH7="Yes")),_xlpm.aDn,(--($P7="Active"))*(--($R7="Yes"))*(--((($S7="Yes")+($S7=TRUE))>0))+(--($T7="Active"))*(--($V7="Yes"))*(--((($W7="Yes")+($W7=TRUE))>0))+(--($X7="Active"))*(--($Z7="Yes"))*(--((($AA7="Yes")+($AA7=TRUE))>0))+(--($AB7="Active"))*(--($AD7="Yes"))*(--((($AE7="Yes")+($AE7=TRUE))>0))+(--($AF7="Active"))*(--($AH7="Yes"))*(--((($AI7="Yes")+($AI7=TRUE))>0)),_xlpm.inPlay,_xlpm.ns+_xlpm.wd+_xlpm.sb+_xlpm.ap,IF(AND(_xlpm.ac>0,_xlpm.inPlay=0,_xlpm.aDn=_xlpm.ac),"LIVE DLR",IF(AND(_xlpm.aRS>0,_xlpm.aDn<_xlpm.aRS),"Training",IF(_xlpm.aRS>0,"Active",IF(AND(_xlpm.dc>0,_xlpm.inPlay+_xlpm.ac=0),"Dead",IF(OR($CA7="Yes",$CA7=TRUE),"Rate Sheet",IF(AND($AJ7<>"",$AK7=FALSE),"Waiting on Dealer",IF(_xlpm.sb>0,"Waiting on Lender",IF(AND(_xlpm.ap+_xlpm.ac>0,_xlpm.ns+_xlpm.wd=0),"Rate Sheet","Application Submitted")))))))))) -> Active | M7: 46202 | N7: 46280 | P7: Declined | Q7: =IF(OR(Q7="",Q7=0),IF($P7="Submitted",TODAY(),""),Q7) | R7: No | S7: No | T7: Declined | U7: =IF(OR(U7="",U7=0),IF($T7="Submitted",TODAY(),""),U7) | V7: No | W7: No | X7: Active | Y7: 46217 | Z7: Yes | AA7: Yes | AB7: N/A | AC7: =IF(OR(AC7="",AC7=0),IF($AB7="Submitted",TODAY(),""),AC7) | AD7: No | AE7: No | AF7: Submitted | AG7: 46275 | AH7: No | AI7: No | AJ7: US Bank needs financial statements | AK7: FALSE | AL7: {=IF($A7="","",SUMPRODUCT((CHOOSE({1,2,3,4,5},$R7,$V7,$Z7,$AD7,$AH7)="Yes")*(((CHOOSE({1,2,3,4,5},$S7,$W7,$AA7,$AE7,$AI7)="Yes")+(CHOOSE({1,2,3,4,5},$S7,$W7,$AA7,$AE7,$AI7)=TRUE))>0)))} -> 1 | AM7: 46287 | AN7: =IF(OR($A7="",$AM7=""),"",TODAY()-$AM7) -> 1 | AT7: 36161000 | BA7: 3 | BZ7: Unassigned | CA7: No | CB7: =IF($A7="","",_xlfn.LET(_xlpm.sfp,AND($P7<>"",$P7<>"N/A",$P7<>"No Min RQ"),_xlpm.slp,AND($T7<>"",$T7<>"N/A",$T7<>"No Min RQ"),_xlpm.ffp,AND($X7<>"",$X7<>"N/A",$X7<>"No Min RQ"),_xlpm.chp,AND($AB7<>"",$AB7<>"N/A",$AB7<>"No Min RQ"),_xlpm.usp,AND($AF7<>"",$AF7<>"N/A",$AF7<>"No Min RQ"),_xlpm.n,_xlpm.sfp+_xlpm.slp+_xlpm.ffp+_xlpm.chp+_xlpm.usp,_xlpm.sub,(_xlpm.sfp*($P7="Submitted"))+(_xlpm.slp*($T7="Submitted"))+(_xlpm.ffp*($X7="Submitted"))+(_xlpm.chp*($AB7="Submitted"))+(_xlpm.usp*($AF7="Submitted")),_xlpm.term,(_xlpm.sfp*OR($P7="Approved",$P7="Declined"))+(_xlpm.slp*OR($T7="Approved",$T7="Declined"))+(_xlpm.ffp*OR($X7="Approved",$X7="Declined"))+(_xlpm.chp*OR($AB7="Approved",$AB7="Declined"))+(_xlpm.usp*OR($AF7="Approved",$AF7="Declined")),IF(_xlpm.n=0,"No applicable lenders",IF(_xlpm.sub>0,"Stays with Shaw - lender still Submitted",IF(_xlpm.term=_xlpm.n,"Clear - all applicable lenders Approved or Declined","Stays with Shaw - not all lenders Approved or Declined")))))
A8: Vet Home Restoration LLC | B8: Frontline Heating and Air | D8: Travis Fincher | E8: 435-525-0050 | F8: travis@frontlineair.com | G8: Steve Stonebraker | H8: stonebraker@getfinti.com | I8: HVAC Equipment, air and water quality | L8: =IF($A8="","",_xlfn.LET(_xlpm.ns,(--($P8="Ready 2 Submit"))+(--($T8="Ready 2 Submit"))+(--($X8="Ready 2 Submit"))+(--($AB8="Ready 2 Submit"))+(--($AF8="Ready 2 Submit")),_xlpm.wd,(--($P8="Waiting on Dealer"))+(--($T8="Waiting on Dealer"))+(--($X8="Waiting on Dealer"))+(--($AB8="Waiting on Dealer"))+(--($AF8="Waiting on Dealer")),_xlpm.sb,(--($P8="Submitted"))+(--($T8="Submitted"))+(--($X8="Submitted"))+(--($AB8="Submitted"))+(--($AF8="Submitted")),_xlpm.ap,(--($P8="Approved"))+(--($T8="Approved"))+(--($X8="Approved"))+(--($AB8="Approved"))+(--($AF8="Approved")),_xlpm.ac,(--($P8="Active"))+(--($T8="Active"))+(--($X8="Active"))+(--($AB8="Active"))+(--($AF8="Active")),_xlpm.dc,(--($P8="Declined"))+(--($T8="Declined"))+(--($X8="Declined"))+(--($AB8="Declined"))+(--($AF8="Declined")),_xlpm.aRS,(--($P8="Active"))*(--($R8="Yes"))+(--($T8="Active"))*(--($V8="Yes"))+(--($X8="Active"))*(--($Z8="Yes"))+(--($AB8="Active"))*(--($AD8="Yes"))+(--($AF8="Active"))*(--($AH8="Yes")),_xlpm.aDn,(--($P8="Active"))*(--($R8="Yes"))*(--((($S8="Yes")+($S8=TRUE))>0))+(--($T8="Active"))*(--($V8="Yes"))*(--((($W8="Yes")+($W8=TRUE))>0))+(--($X8="Active"))*(--($Z8="Yes"))*(--((($AA8="Yes")+($AA8=TRUE))>0))+(--($AB8="Active"))*(--($AD8="Yes"))*(--((($AE8="Yes")+($AE8=TRUE))>0))+(--($AF8="Active"))*(--($AH8="Yes"))*(--((($AI8="Yes")+($AI8=TRUE))>0)),_xlpm.inPlay,_xlpm.ns+_xlpm.wd+_xlpm.sb+_xlpm.ap,IF(AND(_xlpm.ac>0,_xlpm.inPlay=0,_xlpm.aDn=_xlpm.ac),"LIVE DLR",IF(AND(_xlpm.aRS>0,_xlpm.aDn<_xlpm.aRS),"Training",IF(_xlpm.aRS>0,"Active",IF(AND(_xlpm.dc>0,_xlpm.inPlay+_xlpm.ac=0),"Dead",IF(OR($CA8="Yes",$CA8=TRUE),"Rate Sheet",IF(AND($AJ8<>"",$AK8=FALSE),"Waiting on Dealer",IF(_xlpm.sb>0,"Waiting on Lender",IF(AND(_xlpm.ap+_xlpm.ac>0,_xlpm.ns+_xlpm.wd=0),"Rate Sheet","Application Submitted")))))))))) -> LIVE DLR | M8: 46202 | N8: 46280 | O8: 1. Service Finance, 2. Sunlight, 3. Foundation Finance | P8: Active | Q8: 46274 | R8: Yes | S8: Yes | T8: Active | U8: 46274 | V8: Yes | W8: Yes | X8: Active | Y8: 46143 | Z8: Yes | AA8: Yes | AB8: Active | AC8: 46274 | AD8: Yes | AE8: Yes | AF8: N/A | AG8: =IF(OR(AG8="",AG8=0),IF($AF8="Submitted",TODAY(),""),AG8) | AH8: No | AI8: No | AJ8: Complete | AK8: TRUE | AL8: {=IF($A8="","",SUMPRODUCT((CHOOSE({1,2,3,4,5},$R8,$V8,$Z8,$AD8,$AH8)="Yes")*(((CHOOSE({1,2,3,4,5},$S8,$W8,$AA8,$AE8,$AI8)="Yes")+(CHOOSE({1,2,3,4,5},$S8,$W8,$AA8,$AE8,$AI8)=TRUE))>0)))} -> 4 | AN8: =IF(OR($A8="",$AM8=""),"",TODAY()-$AM8) | AP8: 203125329 | AR8: frontline-finti@sunlightfinancial.com; 418327 | AS8: UT | AT8: 35536000 | AU8: UT, NV, AZ | AV8: 4112997000246468065 | BA8: 4 | BZ8: Unassigned | CA8: No | CB8: =IF($A8="","",_xlfn.LET(_xlpm.sfp,AND($P8<>"",$P8<>"N/A",$P8<>"No Min RQ"),_xlpm.slp,AND($T8<>"",$T8<>"N/A",$T8<>"No Min RQ"),_xlpm.ffp,AND($X8<>"",$X8<>"N/A",$X8<>"No Min RQ"),_xlpm.chp,AND($AB8<>"",$AB8<>"N/A",$AB8<>"No Min RQ"),_xlpm.usp,AND($AF8<>"",$AF8<>"N/A",$AF8<>"No Min RQ"),_xlpm.n,_xlpm.sfp+_xlpm.slp+_xlpm.ffp+_xlpm.chp+_xlpm.usp,_xlpm.sub,(_xlpm.sfp*($P8="Submitted"))+(_xlpm.slp*($T8="Submitted"))+(_xlpm.ffp*($X8="Submitted"))+(_xlpm.chp*($AB8="Submitted"))+(_xlpm.usp*($AF8="Submitted")),_xlpm.term,(_xlpm.sfp*OR($P8="Approved",$P8="Declined"))+(_xlpm.slp*OR($T8="Approved",$T8="Declined"))+(_xlpm.ffp*OR($X8="Approved",$X8="Declined"))+(_xlpm.chp*OR($AB8="Approved",$AB8="Declined"))+(_xlpm.usp*OR($AF8="Approved",$AF8="Declined")),IF(_xlpm.n=0,"No applicable lenders",IF(_xlpm.sub>0,"Stays with Shaw - lender still Submitted",IF(_xlpm.term=_xlpm.n,"Clear - all applicable lenders Approved or Declined","Stays with Shaw - not all lenders Approved or Declined")))))
A9: Vantage Point Roofing LLC | B9: VP Roofing | D9: Jacob Fullmer | E9: 801-889-8609 | F9: jake@vproofing.com | G9: Steve Stonebraker | H9: stonebraker@getfinti.com | L9: =IF($A9="","",_xlfn.LET(_xlpm.ns,(--($P9="Ready 2 Submit"))+(--($T9="Ready 2 Submit"))+(--($X9="Ready 2 Submit"))+(--($AB9="Ready 2 Submit"))+(--($AF9="Ready 2 Submit")),_xlpm.wd,(--($P9="Waiting on Dealer"))+(--($T9="Waiting on Dealer"))+(--($X9="Waiting on Dealer"))+(--($AB9="Waiting on Dealer"))+(--($AF9="Waiting on Dealer")),_xlpm.sb,(--($P9="Submitted"))+(--($T9="Submitted"))+(--($X9="Submitted"))+(--($AB9="Submitted"))+(--($AF9="Submitted")),_xlpm.ap,(--($P9="Approved"))+(--($T9="Approved"))+(--($X9="Approved"))+(--($AB9="Approved"))+(--($AF9="Approved")),_xlpm.ac,(--($P9="Active"))+(--($T9="Active"))+(--($X9="Active"))+(--($AB9="Active"))+(--($AF9="Active")),_xlpm.dc,(--($P9="Declined"))+(--($T9="Declined"))+(--($X9="Declined"))+(--($AB9="Declined"))+(--($AF9="Declined")),_xlpm.aRS,(--($P9="Active"))*(--($R9="Yes"))+(--($T9="Active"))*(--($V9="Yes"))+(--($X9="Active"))*(--($Z9="Yes"))+(--($AB9="Active"))*(--($AD9="Yes"))+(--($AF9="Active"))*(--($AH9="Yes")),_xlpm.aDn,(--($P9="Active"))*(--($R9="Yes"))*(--((($S9="Yes")+($S9=TRUE))>0))+(--($T9="Active"))*(--($V9="Yes"))*(--((($W9="Yes")+($W9=TRUE))>0))+(--($X9="Active"))*(--($Z9="Yes"))*(--((($AA9="Yes")+($AA9=TRUE))>0))+(--($AB9="Active"))*(--($AD9="Yes"))*(--((($AE9="Yes")+($AE9=TRUE))>0))+(--($AF9="Active"))*(--($AH9="Yes"))*(--((($AI9="Yes")+($AI9=TRUE))>0)),_xlpm.inPlay,_xlpm.ns+_xlpm.wd+_xlpm.sb+_xlpm.ap,IF(AND(_xlpm.ac>0,_xlpm.inPlay=0,_xlpm.aDn=_xlpm.ac),"LIVE DLR",IF(AND(_xlpm.aRS>0,_xlpm.aDn<_xlpm.aRS),"Training",IF(_xlpm.aRS>0,"Active",IF(AND(_xlpm.dc>0,_xlpm.inPlay+_xlpm.ac=0),"Dead",IF(OR($CA9="Yes",$CA9=TRUE),"Rate Sheet",IF(AND($AJ9<>"",$AK9=FALSE),"Waiting on Dealer",IF(_xlpm.sb>0,"Waiting on Lender",IF(AND(_xlpm.ap+_xlpm.ac>0,_xlpm.ns+_xlpm.wd=0),"Rate Sheet","Application Submitted")))))))))) -> LIVE DLR | M9: 46209 | N9: 46209 | O9: 1. Service Finance, 2. Sunlight, 3. Foundation Finance | P9: Active | Q9: 46274 | R9: Yes | S9: Yes | T9: Active | U9: 46274 | V9: Yes | W9: Yes | X9: Active | Y9: 45908 | Z9: Yes | AA9: Yes | AB9: N/A | AC9: =IF(OR(AC9="",AC9=0),IF($AB9="Submitted",TODAY(),""),AC9) | AD9: No | AE9: No | AF9: N/A | AG9: =IF(OR(AG9="",AG9=0),IF($AF9="Submitted",TODAY(),""),AG9) | AH9: No | AI9: No | AJ9: Active | AK9: TRUE | AL9: {=IF($A9="","",SUMPRODUCT((CHOOSE({1,2,3,4,5},$R9,$V9,$Z9,$AD9,$AH9)="Yes")*(((CHOOSE({1,2,3,4,5},$S9,$W9,$AA9,$AE9,$AI9)="Yes")+(CHOOSE({1,2,3,4,5},$S9,$W9,$AA9,$AE9,$AI9)=TRUE))>0)))} -> 3 | AN9: =IF(OR($A9="",$AM9=""),"",TODAY()-$AM9) | AP9: 227125332 | AR9: vproofing-finti@sunlightfinancial.com; 407469 | AT9: 33844000 | BA9: 5 | BZ9: Unassigned | CA9: No | CB9: =IF($A9="","",_xlfn.LET(_xlpm.sfp,AND($P9<>"",$P9<>"N/A",$P9<>"No Min RQ"),_xlpm.slp,AND($T9<>"",$T9<>"N/A",$T9<>"No Min RQ"),_xlpm.ffp,AND($X9<>"",$X9<>"N/A",$X9<>"No Min RQ"),_xlpm.chp,AND($AB9<>"",$AB9<>"N/A",$AB9<>"No Min RQ"),_xlpm.usp,AND($AF9<>"",$AF9<>"N/A",$AF9<>"No Min RQ"),_xlpm.n,_xlpm.sfp+_xlpm.slp+_xlpm.ffp+_xlpm.chp+_xlpm.usp,_xlpm.sub,(_xlpm.sfp*($P9="Submitted"))+(_xlpm.slp*($T9="Submitted"))+(_xlpm.ffp*($X9="Submitted"))+(_xlpm.chp*($AB9="Submitted"))+(_xlpm.usp*($AF9="Submitted")),_xlpm.term,(_xlpm.sfp*OR($P9="Approved",$P9="Declined"))+(_xlpm.slp*OR($T9="Approved",$T9="Declined"))+(_xlpm.ffp*OR($X9="Approved",$X9="Declined"))+(_xlpm.chp*OR($AB9="Approved",$AB9="Declined"))+(_xlpm.usp*OR($AF9="Approved",$AF9="Declined")),IF(_xlpm.n=0,"No applicable lenders",IF(_xlpm.sub>0,"Stays with Shaw - lender still Submitted",IF(_xlpm.term=_xlpm.n,"Clear - all applicable lenders Approved or Declined","Stays with Shaw - not all lenders Approved or Declined")))))
A10: Mahan Home & Commercial Services, LLC | B10: Mahan Roofing | C10: Sales Rabbit | D10: Jesse Mahan | E10: 817-773-8524 | F10: jesse@mahanhcs.com | G10: Steve Stonebraker | H10: stonebraker@getfinti.com | I10: residential & commercial roofing | K10: 1 | L10: =IF($A10="","",_xlfn.LET(_xlpm.ns,(--($P10="Ready 2 Submit"))+(--($T10="Ready 2 Submit"))+(--($X10="Ready 2 Submit"))+(--($AB10="Ready 2 Submit"))+(--($AF10="Ready 2 Submit")),_xlpm.wd,(--($P10="Waiting on Dealer"))+(--($T10="Waiting on Dealer"))+(--($X10="Waiting on Dealer"))+(--($AB10="Waiting on Dealer"))+(--($AF10="Waiting on Dealer")),_xlpm.sb,(--($P10="Submitted"))+(--($T10="Submitted"))+(--($X10="Submitted"))+(--($AB10="Submitted"))+(--($AF10="Submitted")),_xlpm.ap,(--($P10="Approved"))+(--($T10="Approved"))+(--($X10="Approved"))+(--($AB10="Approved"))+(--($AF10="Approved")),_xlpm.ac,(--($P10="Active"))+(--($T10="Active"))+(--($X10="Active"))+(--($AB10="Active"))+(--($AF10="Active")),_xlpm.dc,(--($P10="Declined"))+(--($T10="Declined"))+(--($X10="Declined"))+(--($AB10="Declined"))+(--($AF10="Declined")),_xlpm.aRS,(--($P10="Active"))*(--($R10="Yes"))+(--($T10="Active"))*(--($V10="Yes"))+(--($X10="Active"))*(--($Z10="Yes"))+(--($AB10="Active"))*(--($AD10="Yes"))+(--($AF10="Active"))*(--($AH10="Yes")),_xlpm.aDn,(--($P10="Active"))*(--($R10="Yes"))*(--((($S10="Yes")+($S10=TRUE))>0))+(--($T10="Active"))*(--($V10="Yes"))*(--((($W10="Yes")+($W10=TRUE))>0))+(--($X10="Active"))*(--($Z10="Yes"))*(--((($AA10="Yes")+($AA10=TRUE))>0))+(--($AB10="Active"))*(--($AD10="Yes"))*(--((($AE10="Yes")+($AE10=TRUE))>0))+(--($AF10="Active"))*(--($AH10="Yes"))*(--((($AI10="Yes")+($AI10=TRUE))>0)),_xlpm.inPlay,_xlpm.ns+_xlpm.wd+_xlpm.sb+_xlpm.ap,IF(AND(_xlpm.ac>0,_xlpm.inPlay=0,_xlpm.aDn=_xlpm.ac),"LIVE DLR",IF(AND(_xlpm.aRS>0,_xlpm.aDn<_xlpm.aRS),"Training",IF(_xlpm.aRS>0,"Active",IF(AND(_xlpm.dc>0,_xlpm.inPlay+_xlpm.ac=0),"Dead",IF(OR($CA10="Yes",$CA10=TRUE),"Rate Sheet",IF(AND($AJ10<>"",$AK10=FALSE),"Waiting on Dealer",IF(_xlpm.sb>0,"Waiting on Lender",IF(AND(_xlpm.ap+_xlpm.ac>0,_xlpm.ns+_xlpm.wd=0),"Rate Sheet","Application Submitted")))))))))) -> Waiting on Lender | M10: 46219 | N10: 46219 | P10: Submitted | Q10: 46279 | R10: No | S10: No | T10: Declined | U10: =IF(OR(U10="",U10=0),IF($T10="Submitted",TODAY(),""),U10) | V10: No | W10: No | X10: Active | Y10: 46219 | Z10: No | AA10: No | AB10: N/A | AC10: =IF(OR(AC10="",AC10=0),IF($AB10="Submitted",TODAY(),""),AC10) | AD10: No | AE10: No | AF10: N/A | AG10: =IF(OR(AG10="",AG10=0),IF($AF10="Submitted",TODAY(),""),AG10) | AH10: No | AI10: No | AJ10: Sent to lenders and sent dlr "lenders submitted" email. | AK10: TRUE | AL10: {=IF($A10="","",SUMPRODUCT((CHOOSE({1,2,3,4,5},$R10,$V10,$Z10,$AD10,$AH10)="Yes")*(((CHOOSE({1,2,3,4,5},$S10,$W10,$AA10,$AE10,$AI10)="Yes")+(CHOOSE({1,2,3,4,5},$S10,$W10,$AA10,$AE10,$AI10)=TRUE))>0)))} -> 0 | AM10: 46279 | AN10: =IF(OR($A10="",$AM10=""),"",TODAY()-$AM10) -> 9 | AT10: 36159000 | BA10: 6 | BZ10: Unassigned | CA10: No | CB10: =IF($A10="","",_xlfn.LET(_xlpm.sfp,AND($P10<>"",$P10<>"N/A",$P10<>"No Min RQ"),_xlpm.slp,AND($T10<>"",$T10<>"N/A",$T10<>"No Min RQ"),_xlpm.ffp,AND($X10<>"",$X10<>"N/A",$X10<>"No Min RQ"),_xlpm.chp,AND($AB10<>"",$AB10<>"N/A",$AB10<>"No Min RQ"),_xlpm.usp,AND($AF10<>"",$AF10<>"N/A",$AF10<>"No Min RQ"),_xlpm.n,_xlpm.sfp+_xlpm.slp+_xlpm.ffp+_xlpm.chp+_xlpm.usp,_xlpm.sub,(_xlpm.sfp*($P10="Submitted"))+(_xlpm.slp*($T10="Submitted"))+(_xlpm.ffp*($X10="Submitted"))+(_xlpm.chp*($AB10="Submitted"))+(_xlpm.usp*($AF10="Submitted")),_xlpm.term,(_xlpm.sfp*OR($P10="Approved",$P10="Declined"))+(_xlpm.slp*OR($T10="Approved",$T10="Declined"))+(_xlpm.ffp*OR($X10="Approved",$X10="Declined"))+(_xlpm.chp*OR($AB10="Approved",$AB10="Declined"))+(_xlpm.usp*OR($AF10="Approved",$AF10="Declined")),IF(_xlpm.n=0,"No applicable lenders",IF(_xlpm.sub>0,"Stays with Shaw - lender still Submitted",IF(_xlpm.term=_xlpm.n,"Clear - all applicable lenders Approved or Declined","Stays with Shaw - not all lenders Approved or Declined")))))
A11: Tetra Walls, Inc. | B11: Tetra | D11: Trevor Taves | E11: 319-540-9542 | F11: trevor@tavesco.com | G11: Steve Stonebraker | H11: stonebraker@getfinti.com | I11: HVAC | K11: 1 | L11: =IF($A11="","",_xlfn.LET(_xlpm.ns,(--($P11="Ready 2 Submit"))+(--($T11="Ready 2 Submit"))+(--($X11="Ready 2 Submit"))+(--($AB11="Ready 2 Submit"))+(--($AF11="Ready 2 Submit")),_xlpm.wd,(--($P11="Waiting on Dealer"))+(--($T11="Waiting on Dealer"))+(--($X11="Waiting on Dealer"))+(--($AB11="Waiting on Dealer"))+(--($AF11="Waiting on Dealer")),_xlpm.sb,(--($P11="Submitted"))+(--($T11="Submitted"))+(--($X11="Submitted"))+(--($AB11="Submitted"))+(--($AF11="Submitted")),_xlpm.ap,(--($P11="Approved"))+(--($T11="Approved"))+(--($X11="Approved"))+(--($AB11="Approved"))+(--($AF11="Approved")),_xlpm.ac,(--($P11="Active"))+(--($T11="Active"))+(--($X11="Active"))+(--($AB11="Active"))+(--($AF11="Active")),_xlpm.dc,(--($P11="Declined"))+(--($T11="Declined"))+(--($X11="Declined"))+(--($AB11="Declined"))+(--($AF11="Declined")),_xlpm.aRS,(--($P11="Active"))*(--($R11="Yes"))+(--($T11="Active"))*(--($V11="Yes"))+(--($X11="Active"))*(--($Z11="Yes"))+(--($AB11="Active"))*(--($AD11="Yes"))+(--($AF11="Active"))*(--($AH11="Yes")),_xlpm.aDn,(--($P11="Active"))*(--($R11="Yes"))*(--((($S11="Yes")+($S11=TRUE))>0))+(--($T11="Active"))*(--($V11="Yes"))*(--((($W11="Yes")+($W11=TRUE))>0))+(--($X11="Active"))*(--($Z11="Yes"))*(--((($AA11="Yes")+($AA11=TRUE))>0))+(--($AB11="Active"))*(--($AD11="Yes"))*(--((($AE11="Yes")+($AE11=TRUE))>0))+(--($AF11="Active"))*(--($AH11="Yes"))*(--((($AI11="Yes")+($AI11=TRUE))>0)),_xlpm.inPlay,_xlpm.ns+_xlpm.wd+_xlpm.sb+_xlpm.ap,IF(AND(_xlpm.ac>0,_xlpm.inPlay=0,_xlpm.aDn=_xlpm.ac),"LIVE DLR",IF(AND(_xlpm.aRS>0,_xlpm.aDn<_xlpm.aRS),"Training",IF(_xlpm.aRS>0,"Active",IF(AND(_xlpm.dc>0,_xlpm.inPlay+_xlpm.ac=0),"Dead",IF(OR($CA11="Yes",$CA11=TRUE),"Rate Sheet",IF(AND($AJ11<>"",$AK11=FALSE),"Waiting on Dealer",IF(_xlpm.sb>0,"Waiting on Lender",IF(AND(_xlpm.ap+_xlpm.ac>0,_xlpm.ns+_xlpm.wd=0),"Rate Sheet","Application Submitted")))))))))) -> Active | M11: 46224 | N11: 46280 | O11: 1. Service 2. Foundation 3. Chowder | P11: Approved | Q11: 46274 | R11: No | S11: No | T11: Active | U11: 46274 | V11: Yes | W11: Yes | X11: Active | Y11: 46231 | Z11: No | AA11: No | AB11: Active | AC11: 46274 | AD11: Yes | AE11: Yes | AF11: N/A | AG11: =IF(OR(AG11="",AG11=0),IF($AF11="Submitted",TODAY(),""),AG11) | AH11: No | AI11: No | AJ11: In process see lender cells....7/23 recieved file share with all the docs needed. Tetra is still pending with SF 8/18/2026 | AK11: TRUE | AL11: {=IF($A11="","",SUMPRODUCT((CHOOSE({1,2,3,4,5},$R11,$V11,$Z11,$AD11,$AH11)="Yes")*(((CHOOSE({1,2,3,4,5},$S11,$W11,$AA11,$AE11,$AI11)="Yes")+(CHOOSE({1,2,3,4,5},$S11,$W11,$AA11,$AE11,$AI11)=TRUE))>0)))} -> 2 | AN11: =IF(OR($A11="",$AM11=""),"",TODAY()-$AM11) | AP11: 227125334 | AQ11: GA,MA,NY | AR11: tetra-finti@sunlightfinancial.com. syG9CRFpYO%7AO!IUr Dealer code: 939375 | AS11: GA | AT11: 36396000 | AU11: GA | AV11: 4112997000256801510 | BA11: 7 | BZ11: Unassigned | CA11: No | CB11: =IF($A11="","",_xlfn.LET(_xlpm.sfp,AND($P11<>"",$P11<>"N/A",$P11<>"No Min RQ"),_xlpm.slp,AND($T11<>"",$T11<>"N/A",$T11<>"No Min RQ"),_xlpm.ffp,AND($X11<>"",$X11<>"N/A",$X11<>"No Min RQ"),_xlpm.chp,AND($AB11<>"",$AB11<>"N/A",$AB11<>"No Min RQ"),_xlpm.usp,AND($AF11<>"",$AF11<>"N/A",$AF11<>"No Min RQ"),_xlpm.n,_xlpm.sfp+_xlpm.slp+_xlpm.ffp+_xlpm.chp+_xlpm.usp,_xlpm.sub,(_xlpm.sfp*($P11="Submitted"))+(_xlpm.slp*($T11="Submitted"))+(_xlpm.ffp*($X11="Submitted"))+(_xlpm.chp*($AB11="Submitted"))+(_xlpm.usp*($AF11="Submitted")),_xlpm.term,(_xlpm.sfp*OR($P11="Approved",$P11="Declined"))+(_xlpm.slp*OR($T11="Approved",$T11="Declined"))+(_xlpm.ffp*OR($X11="Approved",$X11="Declined"))+(_xlpm.chp*OR($AB11="Approved",$AB11="Declined"))+(_xlpm.usp*OR($AF11="Approved",$AF11="Declined")),IF(_xlpm.n=0,"No applicable lenders",IF(_xlpm.sub>0,"Stays with Shaw - lender still Submitted",IF(_xlpm.term=_xlpm.n,"Clear - all applicable lenders Approved or Declined","Stays with Shaw - not all lenders Approved or Declined")))))
A12: Black Sage Construction LLC | B12: Banyan Construction | D12: Brenda LaMont | E12: 801-372-6326 | F12: brenda@banyanbuild.com | G12: Clint Cowley | H12: sales@gowefund.com, clint@gowefund.com | I12: General Contractor | K12: 2 | L12: =IF($A12="","",_xlfn.LET(_xlpm.ns,(--($P12="Ready 2 Submit"))+(--($T12="Ready 2 Submit"))+(--($X12="Ready 2 Submit"))+(--($AB12="Ready 2 Submit"))+(--($AF12="Ready 2 Submit")),_xlpm.wd,(--($P12="Waiting on Dealer"))+(--($T12="Waiting on Dealer"))+(--($X12="Waiting on Dealer"))+(--($AB12="Waiting on Dealer"))+(--($AF12="Waiting on Dealer")),_xlpm.sb,(--($P12="Submitted"))+(--($T12="Submitted"))+(--($X12="Submitted"))+(--($AB12="Submitted"))+(--($AF12="Submitted")),_xlpm.ap,(--($P12="Approved"))+(--($T12="Approved"))+(--($X12="Approved"))+(--($AB12="Approved"))+(--($AF12="Approved")),_xlpm.ac,(--($P12="Active"))+(--($T12="Active"))+(--($X12="Active"))+(--($AB12="Active"))+(--($AF12="Active")),_xlpm.dc,(--($P12="Declined"))+(--($T12="Declined"))+(--($X12="Declined"))+(--($AB12="Declined"))+(--($AF12="Declined")),_xlpm.aRS,(--($P12="Active"))*(--($R12="Yes"))+(--($T12="Active"))*(--($V12="Yes"))+(--($X12="Active"))*(--($Z12="Yes"))+(--($AB12="Active"))*(--($AD12="Yes"))+(--($AF12="Active"))*(--($AH12="Yes")),_xlpm.aDn,(--($P12="Active"))*(--($R12="Yes"))*(--((($S12="Yes")+($S12=TRUE))>0))+(--($T12="Active"))*(--($V12="Yes"))*(--((($W12="Yes")+($W12=TRUE))>0))+(--($X12="Active"))*(--($Z12="Yes"))*(--((($AA12="Yes")+($AA12=TRUE))>0))+(--($AB12="Active"))*(--($AD12="Yes"))*(--((($AE12="Yes")+($AE12=TRUE))>0))+(--($AF12="Active"))*(--($AH12="Yes"))*(--((($AI12="Yes")+($AI12=TRUE))>0)),_xlpm.inPlay,_xlpm.ns+_xlpm.wd+_xlpm.sb+_xlpm.ap,IF(AND(_xlpm.ac>0,_xlpm.inPlay=0,_xlpm.aDn=_xlpm.ac),"LIVE DLR",IF(AND(_xlpm.aRS>0,_xlpm.aDn<_xlpm.aRS),"Training",IF(_xlpm.aRS>0,"Active",IF(AND(_xlpm.dc>0,_xlpm.inPlay+_xlpm.ac=0),"Dead",IF(OR($CA12="Yes",$CA12=TRUE),"Rate Sheet",IF(AND($AJ12<>"",$AK12=FALSE),"Waiting on Dealer",IF(_xlpm.sb>0,"Waiting on Lender",IF(AND(_xlpm.ap+_xlpm.ac>0,_xlpm.ns+_xlpm.wd=0),"Rate Sheet","Application Submitted")))))))))) -> Waiting on Lender | M12: 46225 | N12: 46280 | O12: FF, SF & SL | P12: Submitted | Q12: 46286 | R12: No | S12: No | T12: No Min RQ | U12: =IF(OR(U12="",U12=0),IF($T12="Submitted",TODAY(),""),U12) | V12: No | W12: No | X12: Approved | Y12: 46267 | Z12: No | AA12: No | AB12: N/A | AC12: =IF(OR(AC12="",AC12=0),IF($AB12="Submitted",TODAY(),""),AC12) | AD12: No | AE12: No | AF12: N/A | AG12: =IF(OR(AG12="",AG12=0),IF($AF12="Submitted",TODAY(),""),AG12) | AH12: No | AI12: No | AJ12: IDK how to catagorize in SFC APP. Foundation approved 9/21/26 - owner call done. | AK12: TRUE | AL12: {=IF($A12="","",SUMPRODUCT((CHOOSE({1,2,3,4,5},$R12,$V12,$Z12,$AD12,$AH12)="Yes")*(((CHOOSE({1,2,3,4,5},$S12,$W12,$AA12,$AE12,$AI12)="Yes")+(CHOOSE({1,2,3,4,5},$S12,$W12,$AA12,$AE12,$AI12)=TRUE))>0)))} -> 0 | AM12: 46281 | AN12: =IF(OR($A12="",$AM12=""),"",TODAY()-$AM12) -> 7 | AT12: 36579000 | BA12: 8 | BZ12: Unassigned | CA12: No | CB12: =IF($A12="","",_xlfn.LET(_xlpm.sfp,AND($P12<>"",$P12<>"N/A",$P12<>"No Min RQ"),_xlpm.slp,AND($T12<>"",$T12<>"N/A",$T12<>"No Min RQ"),_xlpm.ffp,AND($X12<>"",$X12<>"N/A",$X12<>"No Min RQ"),_xlpm.chp,AND($AB12<>"",$AB12<>"N/A",$AB12<>"No Min RQ"),_xlpm.usp,AND($AF12<>"",$AF12<>"N/A",$AF12<>"No Min RQ"),_xlpm.n,_xlpm.sfp+_xlpm.slp+_xlpm.ffp+_xlpm.chp+_xlpm.usp,_xlpm.sub,(_xlpm.sfp*($P12="Submitted"))+(_xlpm.slp*($T12="Submitted"))+(_xlpm.ffp*($X12="Submitted"))+(_xlpm.chp*($AB12="Submitted"))+(_xlpm.usp*($AF12="Submitted")),_xlpm.term,(_xlpm.sfp*OR($P12="Approved",$P12="Declined"))+(_xlpm.slp*OR($T12="Approved",$T12="Declined"))+(_xlpm.ffp*OR($X12="Approved",$X12="Declined"))+(_xlpm.chp*OR($AB12="Approved",$AB12="Declined"))+(_xlpm.usp*OR($AF12="Approved",$AF12="Declined")),IF(_xlpm.n=0,"No applicable lenders",IF(_xlpm.sub>0,"Stays with Shaw - lender still Submitted",IF(_xlpm.term=_xlpm.n,"Clear - all applicable lenders Approved or Declined","Stays with Shaw - not all lenders Approved or Declined")))))
